<?xml version="1.0"?>


<root xmlns:xi="http://www.w3.org/2001/XInclude"
	xmlns:gazebo="http://playerstage.sourceforge.net/gazebo/xmlschema/#gz"
    xmlns:model="http://playerstage.sourceforge.net/gazebo/xmlschema/#model"
	xmlns:sensor="http://playerstage.sourceforge.net/gazebo/xmlschema/#sensor"
	xmlns:body="http://playerstage.sourceforge.net/gazebo/xmlschema/#body"
    xmlns:geom="http://playerstage.sourceforge.net/gazebo/xmlschema/#geom"
    xmlns:joint="http://playerstage.sourceforge.net/gazebo/xmlschema/#joint"
	xmlns:controller="http://playerstage.sourceforge.net/gazebo/xmlschema/#controller"
	xmlns:interface="http://playerstage.sourceforge.net/gazebo/xmlschema/#interface"
	xmlns:rendering="http://playerstage.sourceforge.net/gazebo/xmlschema/#rendering"
    xmlns:renderable="http://playerstage.sourceforge.net/gazebo/xmlschema/#renderable"
    xmlns:physics="http://playerstage.sourceforge.net/gazebo/xmlschema/#physics"
	xmlns:xacro="http://ros.org/wiki/xacro">



  <xacro:include filename="$(find jaco_model)/urdf/jaco_common.xacro" />

  <property name="link_base" value="jaco_link_base" />
  <property name="link_1" value="jaco_link_1" />
  <property name="link_2" value="jaco_link_2" />
  <property name="link_3" value="jaco_link_3" />
  <property name="link_4" value="jaco_link_4" />
  <property name="link_5" value="jaco_link_5" />
  <property name="link_hand" value="jaco_link_hand" />
  <property name="link_finger_1" value="jaco_link_finger_1" />
  <property name="link_finger_2" value="jaco_link_finger_2" />
  <property name="link_finger_3" value="jaco_link_finger_3" />

  <property name="api_offset" value="0.028" />
  <property name="api_origin" value="jaco_api_origin" />

  <property name="joint_base" value="jaco_joint_base" />
  <property name="joint_base_axis_xyz" value="0 0 0" />
  <property name="joint_base_origin_xyz" value="0 0 0.55" />
  <property name="joint_base_origin_rpy" value="0 0 0" />

  <property name="joint_1" value="jaco_joint_1" />
  <property name="joint_1_axis_xyz" value="0 0 -1" />
  <property name="joint_1_origin_xyz" value="0 0 0.1535" />
  <property name="joint_1_origin_rpy" value="${J_PI} 0 ${J_PI}" />
  <property name="joint_1_lower_limit" value="${-2*J_PI}" />
  <property name="joint_1_upper_limit" value="${2*J_PI}" />

  <property name="joint_2" value="jaco_joint_2" />
  <property name="joint_2_axis_xyz" value="0 0 1" />
  <property name="joint_2_origin_xyz" value="0 0 -0.1185" />
  <property name="joint_2_origin_rpy" value="-${J_PI/2} ${J_PI} 0" />
  <property name="joint_2_lower_limit" value="${-J_PI}" />
  <property name="joint_2_upper_limit" value="${0}" />

  <property name="joint_3" value="jaco_joint_3" />
  <property name="joint_3_axis_xyz" value="0 0 -1" />
  <property name="joint_3_origin_xyz" value="0.41 0 0" />
  <property name="joint_3_origin_rpy" value="${J_PI} 0 ${J_PI/2}" />
  <property name="joint_3_lower_limit" value="${-5*J_PI/4}" />
  <property name="joint_3_upper_limit" value="${1*J_PI/4}" />

  <property name="joint_4" value="jaco_joint_4" />
  <property name="joint_4_axis_xyz" value="0 0 -1" />
  <property name="joint_4_origin_xyz" value="0.207 0 -0.01125" />
  <property name="joint_4_origin_rpy" value="${J_PI} ${J_PI/2} 0" />
  <property name="joint_4_lower_limit" value="${-2*J_PI}" />
  <property name="joint_4_upper_limit" value="${2*J_PI}" />

  <property name="joint_5" value="jaco_joint_5" />
  <property name="joint_5_axis_xyz" value="0 0 -1" />
  <property name="joint_5_origin_xyz" value="0.0343 0 -0.06588" />
  <property name="joint_5_origin_rpy" value="0 -${J_PI/180*55} 0" />
  <property name="joint_5_lower_limit" value="${-2*J_PI}" />
  <property name="joint_5_upper_limit" value="${2*J_PI}" />

  <property name="joint_6" value="jaco_joint_6" />
  <property name="joint_6_axis_xyz" value="0 0 -1" />
  <property name="joint_6_origin_xyz" value="0.0343 0 -0.06588" />
  <property name="joint_6_origin_rpy" value="-${J_PI/180*55} 0 ${J_PI/2}" />
  <property name="joint_6_lower_limit" value="${-2*J_PI}" />
  <property name="joint_6_upper_limit" value="${2*J_PI}" />

  <property name="joint_finger_1" value="jaco_joint_finger_1" />
  <property name="joint_finger_1_axis_xyz" value="0 0 1" />
  <property name="joint_finger_1_origin_xyz" value="-0.03978 0 -0.10071" />
  <property name="joint_finger_1_origin_rpy" value="-1.7983 1.117 3.1416" />
  <property name="joint_finger_1_lower_limit" value="0" />
  <property name="joint_finger_1_upper_limit" value="${J_PI/180*40}" />

  <property name="joint_finger_2" value="jaco_joint_finger_2" />
  <property name="joint_finger_2_axis_xyz" value="0 0 1" />
  <property name="joint_finger_2_origin_xyz" value="0.03569 -0.0216 -0.10071" />
  <property name="joint_finger_2_origin_rpy" value="-1.6222 1.117 -0.23615" />
  <property name="joint_finger_2_lower_limit" value="0" />
  <property name="joint_finger_2_upper_limit" value="${J_PI/180*40}" />

  <property name="joint_finger_3" value="jaco_joint_finger_3" />
  <property name="joint_finger_3_axis_xyz" value="0 0 1" />
  <property name="joint_finger_3_origin_xyz" value="0.03569 0.0216 -0.10071" />
  <property name="joint_finger_3_origin_rpy" value="-1.5161 1.1459 0.23978" />
  <property name="joint_finger_3_lower_limit" value="0" />
  <property name="joint_finger_3_upper_limit" value="${J_PI/180*40}" />

  <property name="link_end_effector"   value="jaco_end_effector" />
  <property name="end_effector_offset" value="0.1687" />

  <xacro:macro name="jaco_arm" params="parent">
    <xacro:jaco_struct parent="${parent}" basename="jaco"/>

    <xacro:jaco_link link_name="${link_finger_1}"/>
    <xacro:jaco_finger_joint joint_name="${joint_finger_1}" type="revolute" parent="${link_hand}" child="${link_finger_1}" joint_axis_xyz="${joint_finger_1_axis_xyz}" joint_origin_xyz="${joint_finger_1_origin_xyz}" joint_origin_rpy="${joint_finger_1_origin_rpy}" lower_limit="${joint_finger_1_lower_limit}" upper_limit="${joint_finger_1_upper_limit}"/>

    <xacro:jaco_link link_name="${link_finger_2}"/>
    <xacro:jaco_finger_joint joint_name="${joint_finger_2}" type="revolute" parent="${link_hand}" child="${link_finger_2}" joint_axis_xyz="${joint_finger_2_axis_xyz}" joint_origin_xyz="${joint_finger_2_origin_xyz}" joint_origin_rpy="${joint_finger_2_origin_rpy}" lower_limit="${joint_finger_2_lower_limit}" upper_limit="${joint_finger_2_upper_limit}"/>

    <xacro:jaco_link link_name="${link_finger_3}"/>
    <xacro:jaco_finger_joint joint_name="${joint_finger_3}" type="revolute" parent="${link_hand}" child="${link_finger_3}" joint_axis_xyz="${joint_finger_3_axis_xyz}" joint_origin_xyz="${joint_finger_3_origin_xyz}" joint_origin_rpy="${joint_finger_3_origin_rpy}" lower_limit="${joint_finger_3_lower_limit}" upper_limit="${joint_finger_3_upper_limit}"/>
  </xacro:macro>
  <joint name="jointarmtochair" type="fixed">
    <parent link="jaco_link_base"/>
    <child link="base_link"/>
    <origin xyz="0.3 0.1778 0" rpy="0 0 ${-1*J_PI/2}" />
  </joint>
<link name="base_link">
    <visual>
      <geometry>
        <box size="0.52 0.51 0.1"/>
      </geometry>
      <origin rpy="0 0 0" xyz="0.0 0 0.1"/>
      <material name="leather">
        <color rgba="0.25 0.5 0.25 1"/>
        <!--texture filename="package://jaco_description/urdf/leather.jpg" /-->
      </material>
    </visual>
    <collision>
      <geometry>
        <box size="0.53 0.52 0.1"/>
      </geometry>
      <origin rpy="0 0 0" xyz="0.0 0 0.1"/>
    </collision>
    <inertial>
      <mass value="150"/>
      <inertia ixx="0.4" iyy="0.4" izz="0.2" ixy="0.0" ixz="0.0" iyz="0.0"/>
    </inertial>
  </link>
  <link name="back">
    <visual>
      <geometry>
        <box size="0.1 0.43 0.52"/>
      </geometry>
      <!--origin rpy="0 0 0" xyz="-0.5 0 0.3"/-->
      <material name="leather"/>
    </visual>
  </link>
  <joint name="base_link_to_back" type="fixed">
    <parent link="base_link"/>
    <child link="back"/>
    <origin xyz="-0.28 0 0.375"/>
  </joint>
   <link name="back_head">
    <visual>
      <geometry>
        <box size="0.1 0.23 0.18"/>
      </geometry>
      <!--origin rpy="0 0 0" xyz="-0.5 0 0.3"/-->
      <material name="leather"/>
    </visual>
  </link>
  <joint name="base_link_to_back_head" type="fixed">
    <parent link="base_link"/>
    <child link="back_head"/>
    <origin xyz="-0.28 0 0.7"/>
  </joint>
 <!--arm rests-->
  <link name="arm_rest_right">
    <visual>
      <geometry>
        <box size="0.41 0.07 0.05"/>
      </geometry>
      <!--origin rpy="0 0 0" xyz="-0.5 0 0.3"/-->
      <material name="leather"/>
    </visual>
  </link>
  <joint name="base_link_to_arm_rest_right" type="fixed">
    <parent link="base_link"/>
    <child link="arm_rest_right"/>
    <origin xyz="-0.12 0.24 0.25"/>
  </joint>
 <link name="arm_rest_left">
    <visual>
      <geometry>
        <box size="0.41 0.07 0.05"/>
      </geometry>
      <!--origin rpy="0 0 0" xyz="-0.5 0 0.3"/-->
      <material name="leather"/>
    </visual>
  </link>
  <joint name="base_link_to_arm_rest_left" type="fixed">
    <parent link="base_link"/>
    <child link="arm_rest_left"/>
    <origin xyz="-0.12 -0.24 0.25"/>
  </joint>
  <!-- main driving wheels -->
  <link name="left_wheel">
    <visual>
      <geometry>
        <cylinder length="0.09" radius="0.125"/>
      </geometry>
      <origin rpy="1.57075 0 0" xyz="0.0 0.0 0.0"/>
      <material name="wheel">
        <color rgba="0.0 0.0 0.9 1"/>
      </material>
    </visual>
    <collision>
      <geometry>
        <cylinder length="0.06" radius="0.12"/>
      </geometry>
      <origin rpy="1.57075 0 0" xyz="0.0 0.0 0.0"/>
    </collision>
  </link>
  <joint name="base_link_to_left_wheel" type="continuous">
    <parent link="base_link"/>
    <child link="left_wheel"/>
    <origin xyz="0.05 0.3 -0.3"/>
    <axis xyz="0 1 0"/>
  </joint>
  <link name="right_wheel">
    <visual>
      <geometry>
        <cylinder length="0.09" radius="0.125"/>
      </geometry>
      <origin rpy="1.57075 0 0" xyz="0.0 0.0 0.0"/>
      <material name="wheel"/>
    </visual>
    <collision>
      <geometry>
        <cylinder length="0.06" radius="0.12"/>
      </geometry>
      <origin rpy="1.57075 0 0" xyz="0.0 0.0 0.0"/>
    </collision>
  </link>
  <joint name="base_link_to_right_wheel" type="continuous">
    <parent link="base_link"/>
    <child link="right_wheel"/>
    <origin xyz="0.05 -0.3 -0.3"/>
    <axis xyz="0 1 0"/>
  </joint>
 <link name="motor_cage">
    <visual>
      <geometry>
        <box size="0.48 0.34 0.25"/>
      </geometry>
      <!--origin rpy="0 0 0" xyz="-0.5 0 0.3"/-->
      <material name="leather"/>
    </visual>
  </link>
  <joint name="base_link_to_motor_cage" type="fixed">
    <parent link="base_link"/>
    <child link="motor_cage"/>
    <origin xyz="0 0 -0.2"/>
  </joint>
 <link name="under_seat">
    <visual>
      <geometry>
        <box size="0.38 0.32 0.04"/>
      </geometry>
      <!--origin rpy="0 0 0" xyz="-0.5 0 0.3"/-->
      <material name="leather"/>
    </visual>
  </link>
  <joint name="base_link_to_under_seat" type="fixed">
    <parent link="base_link"/>
    <child link="under_seat"/>
    <origin xyz="0 0 0"/>
  </joint>
  <link name="foot_plate">
    <visual>
      <geometry>
        <box size="0.44 0.38 0.05"/>
      </geometry>
      <!--origin rpy="0 0 0" xyz="-0.5 0 0.3"/-->
      <material name="leather"/>
    </visual>
  </link>
  <joint name="base_link_to_foot_plate" type="fixed">
    <parent link="base_link"/>
    <child link="foot_plate"/>
    <origin xyz="0.47 0 -0.3"/>
  </joint>

</root>
